<robot name="onshape">
    <link name="base_link">
        <visual>
            <origin xyz="-2.77556e-17 1.9082e-17 0.2032" rpy="0 -0 0" />
            <geometry>
                <mesh filename="file:///home/mackenzie/catkin_ws/src/wheel_time/urdf/base.stl" />
            </geometry>
            <material name="base_material">
                <color rgba="0.647059 0.647059 0.647059 1.0" />
            </material>
        </visual>
        <collision>
            <origin xyz="-2.77556e-17 1.9082e-17 0.2032" rpy="0 -0 0" />
            <geometry>
                <mesh filename="file:///home/mackenzie/catkin_ws/src/wheel_time/urdf/base.stl" />
            </geometry>
            <material name="base_material">
                <color rgba="0.647059 0.647059 0.647059 1.0" />
            </material>
        </collision>
        <inertial>
            <origin xyz="-1.66695e-17 1.72087e-18 0.0335895" rpy="0 0 0" />
            <mass value="11.195" />
            <inertia ixx="0.0514132" ixy="0" ixz="0" iyy="0.102411" iyz="0" izz="0.0926616" />
        </inertial>
    </link>

    <link name="wheel">
        <visual>
            <origin xyz="2.77556e-17 0 0" rpy="1.5708 -0 1.15854e-17" />
            <geometry>
                <mesh filename="file:///home/mackenzie/catkin_ws/src/wheel_time/urdf/wheel.stl" />
            </geometry>
            <material name="wheel_material">
                <color rgba="0.615686 0.811765 0.929412 1.0" />
            </material>
        </visual>
        <collision>
            <origin xyz="2.77556e-17 0 0" rpy="1.5708 -0 1.15854e-17" />
            <geometry>
                <mesh filename="file:///home/mackenzie/catkin_ws/src/wheel_time/urdf/wheel.stl" />
            </geometry>
            <material name="wheel_material">
                <color rgba="0.615686 0.811765 0.929412 1.0" />
            </material>
        </collision>
        <inertial>
            <origin xyz="2.74456e-17 -1.18404e-17 -3.48721e-18" rpy="0 0 0" />
            <mass value="0.534374" />
            <inertia ixx="0.00318283" ixy="4.68928e-19" ixz="0" iyy="0.00318283" iyz="0" izz="0.00592742" />
        </inertial>
    </link>

    <link name="world"></link>
    <joint name="rev" type="continuous">
        <origin xyz="-7.60623e-18 -3.5982e-17 0.2032" rpy="1.5708 -0.868659 3.14159" />
        <parent link="base_link" />
        <child link="wheel" />
        <axis xyz="0 0 1" />
        <limit effort="1" velocity="20" />
        <joint_properties friction="0.0" />
    </joint>

    <joint name="base_joint" type="fixed">
        <origin xyz="0 0 0" rpy="0 0 0" />
        <parent link="world" />
        <child link="base_link" />
    </joint>

    <gazebo reference="wheel">
        <material>Gazebo/Orange</material>
    </gazebo>
    <gazebo>
        <plugin name="gazebo_ros_control" filename="libgazebo_ros_control.so">
            <robotNamespace>/wheel</robotNamespace>
            
        </plugin>

    </gazebo>
    <transmission name="tran1">
        <type>transmission_interface/SimpleTransmission</type>
        <joint name="rev">
            <hardwareInterface>hardware_interface/EffortJointInterface</hardwareInterface>
        </joint>
        <actuator name="motor1">
            <hardwareInterface>hardware_interface/EffortJointInterface</hardwareInterface>
        </actuator>
    </transmission>

</robot>