<robot name="onshape">
<link name="wheel">
<visual>
<origin xyz="-1.41488e-17 -1.56125e-17 0.2032" rpy="0 -0.0149119 0" />
<geometry>
<mesh filename="/home/mackenzie/catkin_ws/src/wheel_time/urdf/wheel.stl"/>
</geometry>
<material name="wheel_material">
<color rgba="0.615686 0.811765 0.929412 1.0"/>
</material>
</visual>
<collision>
<origin xyz="-1.41488e-17 -1.56125e-17 0.2032" rpy="0 -0.0149119 0" />
<geometry>
<mesh filename="/home/mackenzie/catkin_ws/src/wheel_time/urdf/wheel.stl"/>
</geometry>
<material name="wheel_material">
<color rgba="0.615686 0.811765 0.929412 1.0"/>
</material>
</collision>
<inertial>
<origin xyz="-1.46354e-17 -2.08433e-17 0.2032" rpy="0 0 0"/>
<mass value="0.534374" />
<inertia ixx="0.00318283" ixy="0"  ixz="-2.68925e-21" iyy="0.00592742" iyz="0" izz="0.00318283" />
</inertial>
</link>

<link name="base">
<visual>
<origin xyz="0 0 2.77556e-17" rpy="1.5708 -0 0" />
<geometry>
<mesh filename="/home/mackenzie/catkin_ws/src/wheel_time/urdf/base.stl"/>
</geometry>
<material name="base_material">
<color rgba="0.647059 0.647059 0.647059 1.0"/>
</material>
</visual>
<collision>
<origin xyz="0 0 2.77556e-17" rpy="1.5708 -0 0" />
<geometry>
<mesh filename="/home/mackenzie/catkin_ws/src/wheel_time/urdf/base.stl"/>
</geometry>
<material name="base_material">
<color rgba="0.647059 0.647059 0.647059 1.0"/>
</material>
</collision>
<inertial>
<origin xyz="1.16661e-17 0.16961 1.1502e-17" rpy="0 0 0"/>
<mass value="11.195" />
<inertia ixx="0.0514132" ixy="0"  ixz="0" iyy="0.0926616" iyz="0" izz="0.102411" />
</inertial>
</link>

<joint name="rev" type="continuous">
<origin xyz="-2.77556e-17 -8.67362e-18 0.2032" rpy="-1.5708 -0 0" />
<parent link="wheel" />
<child link="base" />
<axis xyz="0 0 1"/>
<limit effort="1" velocity="20" />
<joint_properties friction="0.0"/>
</joint>

<gazebo reference="wheel">
    <material>Gazebo/Orange</material>
</gazebo>

<gazebo>
  <plugin name="gazebo_ros_control" filename="libgazebo_ros_control.so">
    <robotNamespace>/wheel_time</robotNamespace>
  </plugin>
</gazebo>

<transmission name="trans">
    <type>transmission_interface/SimpleTransmission</type>
    <joint name="rev">
        <hardwareInterface>EffortJointInterface</hardwareInterface>
    </joint>
    <actuator name="motor2">
        <hardwareInterface>EffortJointInterface</hardwareInterface>
        <mechanicalReduction>1</mechanicalReduction>
    </actuator>
</transmission>

</robot>